data/output/GLO.txt
PASSIVE BUY 2940.00 @ 510.69
PASSIVE BUY 2900.00 @ 510.67
PASSIVE SELL 500.00 @ 511.14
PASSIVE BUY 1260.00 @ 510.79
PASSIVE SELL 1340.00 @ 511.12
PASSIVE SELL 780.00 @ 510.99
PASSIVE SELL 740.00 @ 510.95
PASSIVE SELL 1700.00 @ 511.01
PASSIVE SELL 820.00 @ 510.90
PASSIVE BUY 2020.00 @ 510.80
PASSIVE SELL 860.00 @ 510.96
CANCEL SELL 500.00 @ 511.14
PASSIVE SELL 1540.00 @ 510.99
AGGRESSIVE BUY 1380.00 @ 510.90
AGGRESSIVE SELL 1500.00 @ 510.80
AGGRESSIVE SELL 700.00 @ 510.80
PASSIVE SELL 660.00 @ 510.96
AGGRESSIVE SELL 460.00 @ 510.79
PASSIVE SELL 1260.00 @ 510.90
AGGRESSIVE SELL 1220.00 @ 510.79
CANCEL SELL 1340.00 @ 511.12
AGGRESSIVE BUY 2380.00 @ 510.81
PASSIVE BUY 1540.00 @ 510.80
PASSIVE SELL 1020.00 @ 511.00
PASSIVE SELL 1420.00 @ 510.85
CANCEL SELL 1700.00 @ 511.01
AGGRESSIVE SELL 2300.00 @ 510.81
PASSIVE BUY 2420.00 @ 510.72
AGGRESSIVE BUY 860.00 @ 510.85
AGGRESSIVE BUY 2860.00 @ 510.95
PASSIVE SELL 1660.00 @ 511.09
AGGRESSIVE BUY 2820.00 @ 510.99
AGGRESSIVE BUY 2700.00 @ 511.09
PASSIVE SELL 420.00 @ 511.04
PASSIVE BUY 2100.00 @ 511.02
CANCEL BUY 2940.00 @ 510.69
CANCEL BUY 2900.00 @ 510.67
CANCEL BUY 40.00 @ 510.81
CANCEL BUY 1540.00 @ 510.80
CANCEL BUY 2420.00 @ 510.72
CANCEL BUY 300.00 @ 510.95
CANCEL BUY 2100.00 @ 511.02
PASSIVE SELL 1060.00 @ 511.06
AGGRESSIVE BUY 1380.00 @ 511.04
PASSIVE BUY 2060.00 @ 511.01
AGGRESSIVE SELL 2300.00 @ 511.02
PASSIVE SELL 460.00 @ 511.16
PASSIVE SELL 1100.00 @ 511.11
PASSIVE SELL 660.00 @ 511.04
AGGRESSIVE SELL 1100.00 @ 511.01
PASSIVE SELL 1020.00 @ 511.14
CANCEL SELL 460.00 @ 511.16
AGGRESSIVE SELL 660.00 @ 511.01
AGGRESSIVE BUY 1460.00 @ 511.04
AGGRESSIVE BUY 2460.00 @ 511.09
AGGRESSIVE BUY 900.00 @ 511.11
PASSIVE BUY 820.00 @ 510.94
PASSIVE BUY 1500.00 @ 511.05
AGGRESSIVE SELL 1500.00 @ 511.05
PASSIVE SELL 1460.00 @ 511.02
PASSIVE SELL 540.00 @ 511.09
AGGRESSIVE BUY 1020.00 @ 511.02
PASSIVE SELL 2220.00 @ 511.13
PASSIVE SELL 1900.00 @ 511.12
AGGRESSIVE BUY 2620.00 @ 511.12
PASSIVE BUY 2740.00 @ 511.08
AGGRESSIVE SELL 1460.00 @ 511.08
PASSIVE BUY 2460.00 @ 511.07
AGGRESSIVE SELL 900.00 @ 511.08
PASSIVE BUY 1380.00 @ 510.97
PASSIVE SELL 540.00 @ 511.13
PASSIVE BUY 1380.00 @ 511.06
AGGRESSIVE SELL 980.00 @ 511.07
AGGRESSIVE SELL 1820.00 @ 511.07
AGGRESSIVE SELL 1220.00 @ 511.07
PASSIVE SELL 1340.00 @ 511.08
PASSIVE SELL 1300.00 @ 511.17
PASSIVE BUY 980.00 @ 510.96
AGGRESSIVE SELL 780.00 @ 511.06
PASSIVE BUY 2500.00 @ 511.01
PASSIVE SELL 980.00 @ 511.09
CANCEL SELL 1300.00 @ 511.17
PASSIVE SELL 540.00 @ 511.19
CANCEL SELL 540.00 @ 511.19
AGGRESSIVE BUY 2660.00 @ 511.09
PASSIVE BUY 1140.00 @ 511.03
AGGRESSIVE SELL 2020.00 @ 511.01
PASSIVE BUY 2100.00 @ 511.04
PASSIVE SELL 580.00 @ 511.22
PASSIVE BUY 1580.00 @ 510.94
AGGRESSIVE SELL 1700.00 @ 511.04
AGGRESSIVE BUY 1420.00 @ 511.12
PASSIVE BUY 1340.00 @ 511.10
AGGRESSIVE SELL 1420.00 @ 511.04
PASSIVE SELL 1220.00 @ 511.12
PASSIVE BUY 2220.00 @ 511.06
PASSIVE SELL 900.00 @ 511.10
PASSIVE SELL 780.00 @ 511.17
AGGRESSIVE SELL 1140.00 @ 511.06
AGGRESSIVE BUY 1980.00 @ 511.12
AGGRESSIVE SELL 740.00 @ 511.06
AGGRESSIVE BUY 1860.00 @ 511.13
PASSIVE SELL 1660.00 @ 511.18
PASSIVE SELL 500.00 @ 511.14
AGGRESSIVE BUY 2540.00 @ 511.14
PASSIVE BUY 1740.00 @ 511.00
CANCEL BUY -20.00 @ 511.01
CANCEL BUY -820.00 @ 510.94
CANCEL BUY 1380.00 @ 510.97
CANCEL BUY 980.00 @ 510.96
CANCEL BUY 2500.00 @ 511.01
CANCEL BUY 320.00 @ 511.04
CANCEL BUY 1580.00 @ 510.94
CANCEL BUY 340.00 @ 511.06
CANCEL BUY 1740.00 @ 511.00
PASSIVE SELL 1100.00 @ 511.05
AGGRESSIVE BUY 1620.00 @ 511.08
PASSIVE BUY 1100.00 @ 511.03
AGGRESSIVE SELL 2100.00 @ 511.04
PASSIVE BUY 1060.00 @ 510.98
PASSIVE SELL 1020.00 @ 511.15
AGGRESSIVE BUY 2060.00 @ 511.06
AGGRESSIVE BUY 1140.00 @ 511.14
PASSIVE SELL 1060.00 @ 511.23
AGGRESSIVE BUY 1740.00 @ 511.17
AGGRESSIVE BUY 1100.00 @ 511.18
AGGRESSIVE SELL 540.00 @ 511.14
PASSIVE BUY 2180.00 @ 510.99
PASSIVE BUY 2820.00 @ 511.13
PASSIVE BUY 820.00 @ 511.01
CANCEL BUY 1100.00 @ 511.03
CANCEL BUY 1060.00 @ 510.98
CANCEL BUY 480.00 @ 511.06
CANCEL BUY 560.00 @ 511.14
CANCEL BUY 2180.00 @ 510.99
CANCEL BUY 2820.00 @ 511.13
CANCEL BUY 820.00 @ 511.01
PASSIVE SELL 660.00 @ 511.23
PASSIVE BUY 1780.00 @ 511.03
AGGRESSIVE SELL 1340.00 @ 511.03
PASSIVE SELL 500.00 @ 511.08
PASSIVE BUY 2740.00 @ 510.97
AGGRESSIVE SELL 2140.00 @ 510.99
PASSIVE BUY 2580.00 @ 510.94
AGGRESSIVE SELL 2180.00 @ 510.97
AGGRESSIVE BUY 2420.00 @ 511.11
AGGRESSIVE SELL 900.00 @ 511.07
PASSIVE BUY 1100.00 @ 510.93
AGGRESSIVE BUY 1460.00 @ 511.13
PASSIVE SELL 1140.00 @ 511.14
AGGRESSIVE BUY 2940.00 @ 511.23
PASSIVE SELL 1180.00 @ 511.24
AGGRESSIVE SELL 1380.00 @ 511.05
PASSIVE SELL 740.00 @ 511.02
AGGRESSIVE BUY 1740.00 @ 511.14
PASSIVE SELL 2020.00 @ 511.32
AGGRESSIVE SELL 1900.00 @ 511.13
PASSIVE SELL 1980.00 @ 511.13
PASSIVE SELL 1820.00 @ 511.19
PASSIVE BUY 1420.00 @ 510.91
PASSIVE BUY 1300.00 @ 510.90
PASSIVE SELL 900.00 @ 511.03
PASSIVE SELL 460.00 @ 511.12
CANCEL SELL 2020.00 @ 511.32
PASSIVE BUY 1340.00 @ 511.01
PASSIVE SELL 820.00 @ 511.08
CANCEL SELL 1180.00 @ 511.24
AGGRESSIVE SELL 1460.00 @ 510.97
PASSIVE SELL 2220.00 @ 511.13
PASSIVE BUY 2580.00 @ 510.86
PASSIVE SELL 620.00 @ 510.99
CANCEL SELL -460.00 @ 511.23
CANCEL SELL 660.00 @ 511.23
AGGRESSIVE SELL 2220.00 @ 510.94
PASSIVE SELL 2140.00 @ 511.05
CANCEL SELL 1820.00 @ 511.19
PASSIVE SELL 1980.00 @ 511.00
CANCEL SELL -1500.00 @ 511.13
CANCEL SELL -1980.00 @ 511.13
CANCEL SELL 2220.00 @ 511.13
PASSIVE BUY 1620.00 @ 510.86
PASSIVE SELL 1220.00 @ 511.13
CANCEL SELL 1220.00 @ 511.13
PASSIVE SELL 940.00 @ 511.12
AGGRESSIVE SELL 980.00 @ 510.93
PASSIVE BUY 2860.00 @ 510.98
AGGRESSIVE SELL 1540.00 @ 510.98
PASSIVE SELL 1380.00 @ 511.08
PASSIVE BUY 2100.00 @ 510.90
AGGRESSIVE BUY 2020.00 @ 511.00
AGGRESSIVE BUY 1860.00 @ 511.00
PASSIVE BUY 780.00 @ 510.93
PASSIVE SELL 460.00 @ 511.03
PASSIVE SELL 1500.00 @ 511.12
AGGRESSIVE BUY 2060.00 @ 511.05
AGGRESSIVE SELL 1180.00 @ 511.00
AGGRESSIVE SELL 1020.00 @ 510.98
AGGRESSIVE SELL 1340.00 @ 510.93
PASSIVE BUY 2620.00 @ 510.85
AGGRESSIVE SELL 1180.00 @ 510.91
PASSIVE SELL 1940.00 @ 510.95
PASSIVE BUY 2660.00 @ 510.86
PASSIVE SELL 420.00 @ 510.95
PASSIVE SELL 2300.00 @ 510.93
AGGRESSIVE BUY 2620.00 @ 510.95
PASSIVE SELL 1220.00 @ 510.99
AGGRESSIVE SELL 2100.00 @ 510.90
AGGRESSIVE BUY 2900.00 @ 510.95
AGGRESSIVE BUY 1740.00 @ 511.05
PASSIVE SELL 1940.00 @ 510.97
AGGRESSIVE SELL 1740.00 @ 510.90
PASSIVE SELL 1940.00 @ 511.10
PASSIVE BUY 900.00 @ 510.95
PASSIVE SELL 1780.00 @ 510.99
AGGRESSIVE SELL 1340.00 @ 510.92
CANCEL SELL -460.00 @ 511.12
CANCEL SELL -940.00 @ 511.12
CANCEL SELL 1500.00 @ 511.12
PASSIVE SELL 940.00 @ 510.99
PASSIVE SELL 1100.00 @ 510.95
CANCEL SELL 1940.00 @ 511.10
PASSIVE SELL 1020.00 @ 510.96
CANCEL SELL -820.00 @ 511.08
CANCEL SELL 1380.00 @ 511.08
AGGRESSIVE SELL 1620.00 @ 510.90
CANCEL SELL 920.00 @ 511.05
AGGRESSIVE BUY 1580.00 @ 510.95
PASSIVE BUY 1940.00 @ 510.92
PASSIVE BUY 2740.00 @ 510.94
PASSIVE BUY 2580.00 @ 510.90
AGGRESSIVE SELL 860.00 @ 510.94
PASSIVE SELL 540.00 @ 511.00
PASSIVE SELL 1260.00 @ 510.97
AGGRESSIVE SELL 980.00 @ 510.94
PASSIVE BUY 1700.00 @ 510.90
PASSIVE SELL 1820.00 @ 511.06
AGGRESSIVE SELL 1380.00 @ 510.92
PASSIVE BUY 2020.00 @ 510.85
PASSIVE SELL 1300.00 @ 511.00
PASSIVE SELL 1460.00 @ 511.07
CANCEL SELL 1460.00 @ 511.07
AGGRESSIVE SELL 940.00 @ 510.92
AGGRESSIVE BUY 2780.00 @ 510.97
PASSIVE BUY 1220.00 @ 510.85
PASSIVE BUY 2700.00 @ 510.90
AGGRESSIVE SELL 980.00 @ 510.90
PASSIVE SELL 1420.00 @ 510.92
PASSIVE SELL 1620.00 @ 510.91
AGGRESSIVE BUY 980.00 @ 510.91
AGGRESSIVE SELL 700.00 @ 510.90
PASSIVE BUY 1380.00 @ 510.78
AGGRESSIVE BUY 1220.00 @ 510.92
PASSIVE SELL 1700.00 @ 510.96
PASSIVE BUY 2300.00 @ 510.82
AGGRESSIVE SELL 540.00 @ 510.90
AGGRESSIVE BUY 1860.00 @ 510.95
AGGRESSIVE SELL 780.00 @ 510.95
PASSIVE SELL 1180.00 @ 511.11
AGGRESSIVE BUY 1900.00 @ 510.97
PASSIVE SELL 1980.00 @ 510.99
PASSIVE BUY 1020.00 @ 510.88
CANCEL BUY -2580.00 @ 510.86
CANCEL BUY -1620.00 @ 510.86
CANCEL BUY -2620.00 @ 510.85
CANCEL BUY 2660.00 @ 510.86
CANCEL BUY -880.00 @ 510.90
