data/output-ground-truth/20.txt
PASSIVE BUY 1580.00 @ 5.94
PASSIVE SELL 420.00 @ 6.08
PASSIVE SELL 660.00 @ 6.07
PASSIVE BUY 2340.00 @ 6.01
PASSIVE SELL 660.00 @ 6.03
AGGRESSIVE BUY 2060.00 @ 6.07
PASSIVE SELL 1740.00 @ 6.09
AGGRESSIVE BUY 2660.00 @ 6.17
PASSIVE BUY 1620.00 @ 6.16
PASSIVE SELL 460.00 @ 6.32
PASSIVE BUY 2700.00 @ 6.15
PASSIVE BUY 2460.00 @ 6.18
CANCEL BUY 1580.00 @ 5.94
CANCEL BUY 2340.00 @ 6.01
CANCEL BUY 740.00 @ 6.07
CANCEL BUY 500.00 @ 6.17
CANCEL BUY 1620.00 @ 6.16
CANCEL BUY 2700.00 @ 6.15
CANCEL BUY 2460.00 @ 6.18
PASSIVE BUY 820.00 @ 6.19
PASSIVE SELL 940.00 @ 6.20
AGGRESSIVE BUY 1540.00 @ 6.20
PASSIVE BUY 2780.00 @ 6.06
PASSIVE SELL 1660.00 @ 6.36
PASSIVE SELL 1620.00 @ 6.26
PASSIVE BUY 900.00 @ 6.15
PASSIVE BUY 2140.00 @ 6.09
AGGRESSIVE SELL 540.00 @ 6.20
PASSIVE SELL 460.00 @ 6.27
AGGRESSIVE BUY 2260.00 @ 6.28
AGGRESSIVE BUY 2740.00 @ 6.40
CANCEL BUY 820.00 @ 6.19
CANCEL BUY 60.00 @ 6.20
CANCEL BUY 2780.00 @ 6.06
CANCEL BUY 900.00 @ 6.15
CANCEL BUY 2140.00 @ 6.09
CANCEL BUY 180.00 @ 6.28
CANCEL BUY 620.00 @ 6.40
PASSIVE BUY 1700.00 @ 5.71
PASSIVE SELL 2020.00 @ 6.49
PASSIVE BUY 2180.00 @ 5.86
PASSIVE BUY 2220.00 @ 5.82
PASSIVE BUY 740.00 @ 5.78
PASSIVE BUY 2740.00 @ 5.83
PASSIVE BUY 1980.00 @ 6.03
PASSIVE SELL 1100.00 @ 6.54
PASSIVE BUY 2780.00 @ 5.98
CANCEL BUY 1700.00 @ 5.71
CANCEL BUY 2180.00 @ 5.86
CANCEL BUY 2220.00 @ 5.82
CANCEL BUY 740.00 @ 5.78
CANCEL BUY 2740.00 @ 5.83
CANCEL BUY 1980.00 @ 6.03
CANCEL BUY 2780.00 @ 5.98
PASSIVE SELL 700.00 @ 6.56
PASSIVE BUY 1940.00 @ 6.41
PASSIVE BUY 1220.00 @ 6.34
PASSIVE BUY 1780.00 @ 6.35
AGGRESSIVE SELL 1660.00 @ 6.41
AGGRESSIVE BUY 1540.00 @ 6.49
AGGRESSIVE SELL 740.00 @ 6.39
AGGRESSIVE SELL 740.00 @ 6.35
AGGRESSIVE BUY 2860.00 @ 6.44
PASSIVE BUY 1740.00 @ 6.45
AGGRESSIVE BUY 2140.00 @ 6.56
PASSIVE BUY 2380.00 @ 6.39
PASSIVE BUY 2180.00 @ 6.50
PASSIVE BUY 820.00 @ 6.44
AGGRESSIVE SELL 700.00 @ 6.50
PASSIVE BUY 940.00 @ 6.55
CANCEL BUY 1220.00 @ 6.34
CANCEL BUY 1040.00 @ 6.35
CANCEL BUY -2400.00 @ 6.44
CANCEL BUY 1740.00 @ 6.45
CANCEL BUY 2380.00 @ 6.39
CANCEL BUY 1480.00 @ 6.50
CANCEL BUY 820.00 @ 6.44
CANCEL BUY 940.00 @ 6.55
AGGRESSIVE BUY 1540.00 @ 6.56
PASSIVE SELL 940.00 @ 6.69
PASSIVE BUY 2540.00 @ 6.52
PASSIVE BUY 900.00 @ 6.57
PASSIVE BUY 2380.00 @ 6.60
PASSIVE BUY 1180.00 @ 6.48
PASSIVE SELL 780.00 @ 6.72
AGGRESSIVE BUY 1100.00 @ 6.72
PASSIVE SELL 1820.00 @ 6.81
AGGRESSIVE SELL 540.00 @ 6.60
PASSIVE BUY 1220.00 @ 6.51
PASSIVE SELL 1740.00 @ 6.84
PASSIVE BUY 1580.00 @ 6.57
PASSIVE BUY 1340.00 @ 6.66
CANCEL BUY 1400.00 @ 6.56
CANCEL BUY 2540.00 @ 6.52
CANCEL BUY -900.00 @ 6.57
CANCEL BUY 1840.00 @ 6.60
CANCEL BUY 1180.00 @ 6.48
CANCEL BUY 1220.00 @ 6.51
CANCEL BUY 1580.00 @ 6.57
CANCEL BUY 1340.00 @ 6.66
PASSIVE SELL 500.00 @ 6.75
PASSIVE BUY 900.00 @ 6.63
PASSIVE BUY 1300.00 @ 6.56
PASSIVE BUY 1500.00 @ 6.68
AGGRESSIVE SELL 1420.00 @ 6.68
AGGRESSIVE SELL 1100.00 @ 6.66
AGGRESSIVE SELL 2260.00 @ 6.51
PASSIVE BUY 1260.00 @ 6.37
PASSIVE SELL 1420.00 @ 6.60
CANCEL SELL 1740.00 @ 6.84
PASSIVE BUY 1140.00 @ 6.46
PASSIVE BUY 2020.00 @ 6.47
AGGRESSIVE BUY 1860.00 @ 6.60
AGGRESSIVE SELL 1660.00 @ 6.58
PASSIVE BUY 1660.00 @ 6.49
PASSIVE SELL 1660.00 @ 6.69
PASSIVE BUY 1100.00 @ 6.41
AGGRESSIVE SELL 1340.00 @ 6.49
PASSIVE SELL 900.00 @ 6.50
CANCEL SELL 1820.00 @ 6.81
PASSIVE BUY 2100.00 @ 6.48
AGGRESSIVE BUY 1540.00 @ 6.58
AGGRESSIVE BUY 2700.00 @ 6.65
CANCEL BUY 1260.00 @ 6.37
CANCEL BUY 1140.00 @ 6.46
CANCEL BUY 2020.00 @ 6.47
CANCEL BUY 320.00 @ 6.49
CANCEL BUY 1100.00 @ 6.41
CANCEL BUY 2100.00 @ 6.48
CANCEL BUY 2060.00 @ 6.65
PASSIVE BUY 2100.00 @ 6.48
PASSIVE SELL 1100.00 @ 6.52
AGGRESSIVE SELL 2060.00 @ 6.48
PASSIVE BUY 1940.00 @ 6.37
AGGRESSIVE SELL 1380.00 @ 6.37
PASSIVE SELL 1500.00 @ 6.60
PASSIVE SELL 1340.00 @ 6.40
CANCEL SELL 500.00 @ 6.75
PASSIVE SELL 820.00 @ 6.49
CANCEL SELL 620.00 @ 6.72
PASSIVE BUY 2580.00 @ 6.28
AGGRESSIVE SELL 980.00 @ 6.30
CANCEL SELL 1660.00 @ 6.69
AGGRESSIVE SELL 2300.00 @ 6.28
AGGRESSIVE SELL 860.00 @ 6.21
CANCEL SELL 1020.00 @ 6.66
PASSIVE SELL 1180.00 @ 6.13
CANCEL SELL 1500.00 @ 6.60
PASSIVE SELL 1340.00 @ 6.22
CANCEL SELL 1100.00 @ 6.52
AGGRESSIVE BUY 2580.00 @ 6.22
PASSIVE BUY 1940.00 @ 6.16
AGGRESSIVE BUY 1380.00 @ 6.28
AGGRESSIVE SELL 460.00 @ 6.28
PASSIVE SELL 2020.00 @ 6.42
PASSIVE BUY 940.00 @ 6.20
AGGRESSIVE BUY 2220.00 @ 6.42
PASSIVE SELL 780.00 @ 6.31
AGGRESSIVE SELL 820.00 @ 6.22
AGGRESSIVE SELL 1660.00 @ 6.16
PASSIVE BUY 1140.00 @ 6.05
PASSIVE SELL 2100.00 @ 6.24
PASSIVE BUY 2460.00 @ 6.05
AGGRESSIVE SELL 900.00 @ 6.16
AGGRESSIVE SELL 1620.00 @ 6.14
PASSIVE BUY 2260.00 @ 6.07
AGGRESSIVE SELL 460.00 @ 6.07
PASSIVE SELL 860.00 @ 6.19
CANCEL SELL 820.00 @ 6.49
AGGRESSIVE SELL 1900.00 @ 6.07
CANCEL SELL 1520.00 @ 6.42
PASSIVE BUY 2860.00 @ 6.02
AGGRESSIVE SELL 2260.00 @ 6.05
PASSIVE SELL 900.00 @ 6.09
CANCEL SELL 780.00 @ 6.31
PASSIVE BUY 1460.00 @ 5.98
AGGRESSIVE BUY 820.00 @ 6.09
PASSIVE SELL 820.00 @ 6.06
AGGRESSIVE SELL 1100.00 @ 6.05
AGGRESSIVE BUY 2540.00 @ 6.19
AGGRESSIVE SELL 980.00 @ 6.04
AGGRESSIVE BUY 1380.00 @ 6.17
PASSIVE SELL 1940.00 @ 6.26
AGGRESSIVE BUY 2380.00 @ 6.24
AGGRESSIVE SELL 1460.00 @ 6.11
PASSIVE BUY 2220.00 @ 6.05
PASSIVE BUY 2540.00 @ 6.01
AGGRESSIVE SELL 1900.00 @ 6.05
PASSIVE SELL 460.00 @ 6.10
AGGRESSIVE BUY 1060.00 @ 6.11
PASSIVE BUY 1740.00 @ 6.03
PASSIVE BUY 1060.00 @ 5.99
PASSIVE SELL 1860.00 @ 6.10
AGGRESSIVE BUY 1740.00 @ 6.10
PASSIVE SELL 500.00 @ 6.21
PASSIVE SELL 1180.00 @ 6.15
PASSIVE BUY 1340.00 @ 6.04
CANCEL BUY 2860.00 @ 6.02
CANCEL BUY 1460.00 @ 5.98
CANCEL BUY 320.00 @ 6.05
CANCEL BUY 2540.00 @ 6.01
CANCEL BUY 1740.00 @ 6.03
CANCEL BUY 1060.00 @ 5.99
CANCEL BUY 1340.00 @ 6.04
PASSIVE SELL 780.00 @ 6.12
CANCEL SELL 1940.00 @ 6.26
PASSIVE BUY 820.00 @ 6.09
AGGRESSIVE SELL 1620.00 @ 6.06
CANCEL SELL 760.00 @ 6.24
PASSIVE SELL 1380.00 @ 5.90
CANCEL SELL 500.00 @ 6.21
PASSIVE SELL 1940.00 @ 5.76
CANCEL SELL 1180.00 @ 6.15
PASSIVE SELL 2180.00 @ 5.87
CANCEL SELL 780.00 @ 6.12
AGGRESSIVE BUY 1420.00 @ 5.76
PASSIVE SELL 2060.00 @ 5.81
CANCEL SELL 220.00 @ 6.11
AGGRESSIVE BUY 820.00 @ 5.81
PASSIVE SELL 2300.00 @ 5.64
AGGRESSIVE BUY 1140.00 @ 5.64
PASSIVE SELL 1620.00 @ 5.57
CANCEL SELL 120.00 @ 6.10
AGGRESSIVE BUY 1740.00 @ 5.64
AGGRESSIVE BUY 1860.00 @ 5.81
AGGRESSIVE BUY 1180.00 @ 5.87
PASSIVE SELL 1660.00 @ 5.83
PASSIVE SELL 740.00 @ 5.80
PASSIVE SELL 460.00 @ 5.62
PASSIVE SELL 1100.00 @ 5.62
PASSIVE SELL 820.00 @ 5.53
CANCEL SELL 800.00 @ 6.06
PASSIVE SELL 1020.00 @ 5.37
CANCEL SELL 1380.00 @ 5.90
AGGRESSIVE BUY 1060.00 @ 5.53
AGGRESSIVE BUY 2460.00 @ 5.80
AGGRESSIVE BUY 1820.00 @ 5.83
PASSIVE SELL 1980.00 @ 5.79
AGGRESSIVE BUY 1060.00 @ 5.79
PASSIVE SELL 1380.00 @ 5.63
AGGRESSIVE BUY 2060.00 @ 5.79
AGGRESSIVE BUY 1380.00 @ 5.87
AGGRESSIVE BUY 1220.00 @ 5.87
PASSIVE SELL 1660.00 @ 5.85
PASSIVE SELL 660.00 @ 5.81
PASSIVE SELL 1500.00 @ 5.86
AGGRESSIVE BUY 2020.00 @ 5.85
AGGRESSIVE BUY 1300.00 @ 5.86
PASSIVE SELL 620.00 @ 5.97
PASSIVE SELL 2020.00 @ 5.79
PASSIVE SELL 1780.00 @ 5.62
PASSIVE SELL 2140.00 @ 5.63
AGGRESSIVE BUY 1260.00 @ 5.62
PASSIVE SELL 2300.00 @ 5.50
CANCEL SELL 620.00 @ 5.97
AGGRESSIVE BUY 2300.00 @ 5.50
PASSIVE SELL 980.00 @ 5.63
PASSIVE SELL 940.00 @ 5.64
PASSIVE SELL 1660.00 @ 5.58
CANCEL SELL 40.00 @ 5.87
PASSIVE SELL 1620.00 @ 5.56
CANCEL SELL 500.00 @ 5.86
PASSIVE SELL 1340.00 @ 5.40
CANCEL SELL 2020.00 @ 5.79
PASSIVE SELL 1140.00 @ 5.43
CANCEL SELL 940.00 @ 5.64
PASSIVE SELL 1340.00 @ 5.36
CANCEL SELL -2140.00 @ 5.63
CANCEL SELL 980.00 @ 5.63
AGGRESSIVE BUY 2460.00 @ 5.40
PASSIVE SELL 2140.00 @ 5.52
AGGRESSIVE BUY 1060.00 @ 5.43
AGGRESSIVE BUY 1220.00 @ 5.52
AGGRESSIVE BUY 1900.00 @ 5.56
PASSIVE SELL 1300.00 @ 5.42
PASSIVE SELL 2060.00 @ 5.33
AGGRESSIVE BUY 2380.00 @ 5.42
AGGRESSIVE BUY 1100.00 @ 5.56
PASSIVE SELL 1220.00 @ 5.55
PASSIVE SELL 740.00 @ 5.63
PASSIVE SELL 1180.00 @ 5.40
AGGRESSIVE BUY 1860.00 @ 5.55
PASSIVE SELL 620.00 @ 5.63
PASSIVE SELL 820.00 @ 5.44
PASSIVE SELL 2300.00 @ 5.53
CANCEL SELL -740.00 @ 5.63
CANCEL SELL 620.00 @ 5.63
AGGRESSIVE BUY 1900.00 @ 5.53
AGGRESSIVE BUY 2900.00 @ 5.58
